Workbook

Sheet Bid Tracker
A1: GTM Proposal & Bid Tracker - FY2026
A2: Source: FocusNet bid register + SharePoint Proposals Library. Maintained by Anita Rao. Last updated 8 Oct 2026.
A3: Classification: Internal
A5: Bid ID | B5: Opportunity ID | C5: Account | D5: Industry | E5: Bid Type | F5: Service Line | G5: Technical Offering | H5: Deal Value (USD) | I5: RFx Received | J5: Submission Date | K5: Decision Date | L5: Bid Manager | M5: Account Owner | N5: Partner | O5: Competitors | P5: Status | Q5: Win / Loss / No-bid Reason | R5: Cycle Time (days) | S5: Deal Size Band
A6: BID-0541 | B6: OPP-23017 | C6: Northwind Traders | D6: Retail | E6: RFP | F6: Application Modernization | G6: POS Modernisation | H6: 3600000 | I6: 45600 | J6: 45639 | K6: 45702 | L6: Anita Rao | M6: Priya Raman | O6: Infosys; Accenture | P6: Won | Q6: Retail POS references; phased fixed price; strong sponsor (Daniel Okafor) | R6: =IF(AND(K6<>"",OR(P6="Won",P6="Lost")),K6-I6,"") -> 102 | S6: =IF(H6<500000,"< $0.5M",IF(H6<1000000,"$0.5M-1M",IF(H6<3000000,"$1M-3M","> $3M"))) -> > $3M
A7: BID-0546 | B7: OPP-23104 | C7: Halcyon Health | D7: Healthcare | E7: RFP | F7: Data & AI | G7: Microsoft Fabric Analytics | H7: 1100000 | I7: 45670 | J7: 45702 | K7: 45737 | L7: Anita Rao | M7: Hannah Lee | O7: Cognizant; Slalom | P7: Won | Q7: Payer data model accelerator; price 6% below next bidder | R7: =IF(AND(K7<>"",OR(P7="Won",P7="Lost")),K7-I7,"") -> 67 | S7: =IF(H7<500000,"< $0.5M",IF(H7<1000000,"$0.5M-1M",IF(H7<3000000,"$1M-3M","> $3M"))) -> $1M-3M
A8: BID-0549 | B8: OPP-23121 | C8: Wingtip Logistics | D8: Logistics | E8: RFP | F8: Data & AI | G8: Cloud Data Platform (Azure Databricks) | H8: 1600000 | I8: 45698 | J8: 45737 | K8: 45786 | L8: Anita Rao | M8: Sophie Turner | O8: Slalom; EPAM | P8: Won | Q8: Databricks co-sell and 6-week POC on client data | R8: =IF(AND(K8<>"",OR(P8="Won",P8="Lost")),K8-I8,"") -> 88 | S8: =IF(H8<500000,"< $0.5M",IF(H8<1000000,"$0.5M-1M",IF(H8<3000000,"$1M-3M","> $3M"))) -> $1M-3M
A9: BID-0552 | B9: OPP-23166 | C9: Fabrikam Health | D9: Healthcare | E9: RFP | F9: Data & AI | G9: Microsoft Fabric Analytics | H9: 2100000 | I9: 45754 | J9: 45793 | K9: 45863 | L9: Anita Rao | M9: Priya Raman | O9: Deloitte; Cognizant | P9: Won | Q9: HIPAA credentials and Epic Clarity accelerator | R9: =IF(AND(K9<>"",OR(P9="Won",P9="Lost")),K9-I9,"") -> 109 | S9: =IF(H9<500000,"< $0.5M",IF(H9<1000000,"$0.5M-1M",IF(H9<3000000,"$1M-3M","> $3M"))) -> $1M-3M
A10: BID-0555 | B10: OPP-23171 | C10: Lamna Healthcare | D10: Healthcare | E10: RFP | F10: Application Modernization | G10: Legacy to Cloud-Native | H10: 1800000 | I10: 45768 | J10: 45807 | K10: 45856 | L10: Anita Rao | M10: Hannah Lee | O10: Accenture | P10: Lost | Q10: Price 9% higher; client preferred winner's payer platform | R10: =IF(AND(K10<>"",OR(P10="Won",P10="Lost")),K10-I10,"") -> 88 | S10: =IF(H10<500000,"< $0.5M",IF(H10<1000000,"$0.5M-1M",IF(H10<3000000,"$1M-3M","> $3M"))) -> $1M-3M
A11: BID-0557 | B11: OPP-23098 | C11: Tailspin Airlines | D11: Travel & Transport | E11: Proactive proposal | F11: Cloud & Infrastructure | G11: AWS Migration Factory | H11: 1400000 | I11: 45663 | J11: 45695 | K11: 45730 | L11: Rohan Kapoor | M11: Sophie Turner | P11: Won | Q11: MAP funding; 400-server factory plan | R11: =IF(AND(K11<>"",OR(P11="Won",P11="Lost")),K11-I11,"") -> 67 | S11: =IF(H11<500000,"< $0.5M",IF(H11<1000000,"$0.5M-1M",IF(H11<3000000,"$1M-3M","> $3M"))) -> $1M-3M
A12: BID-0560 | B12: OPP-23188 | C12: Contoso Manufacturing | D12: Manufacturing | E12: RFP | F12: Data & AI | G12: Advanced Analytics & ML | H12: 700000 | I12: 45789 | J12: 45821 | K12: 45870 | L12: Anita Rao | M12: Sophie Turner | O12: HCLTech | P12: Lost | Q12: OT integration depth; no OSIsoft PI references | R12: =IF(AND(K12<>"",OR(P12="Won",P12="Lost")),K12-I12,"") -> 81 | S12: =IF(H12<500000,"< $0.5M",IF(H12<1000000,"$0.5M-1M",IF(H12<3000000,"$1M-3M","> $3M"))) -> $0.5M-1M
A13: BID-0563 | C13: Coho Winery | D13: Retail | E13: RFP | F13: Digital Commerce | G13: Unified Commerce Replatform | H13: 900000 | I13: 45796 | J13: 45828 | K13: 45877 | L13: Anita Rao | O13: EPAM | P13: Lost | Q13: Winner had Shopify Plus specialism and lower day rates | R13: =IF(AND(K13<>"",OR(P13="Won",P13="Lost")),K13-I13,"") -> 81 | S13: =IF(H13<500000,"< $0.5M",IF(H13<1000000,"$0.5M-1M",IF(H13<3000000,"$1M-3M","> $3M"))) -> $0.5M-1M
A14: BID-0566 | C14: Lucerne Publishing | D14: Media | E14: RFI | F14: Application Modernization | G14: Legacy to Cloud-Native | H14: 1200000 | I14: 45810 | J14: 45828 | K14: 45849 | L14: Rohan Kapoor | O14: Publicis Sapient | P14: Lost | Q14: Not shortlisted after RFI; weak media references | R14: =IF(AND(K14<>"",OR(P14="Won",P14="Lost")),K14-I14,"") -> 39 | S14: =IF(H14<500000,"< $0.5M",IF(H14<1000000,"$0.5M-1M",IF(H14<3000000,"$1M-3M","> $3M"))) -> $1M-3M
A15: BID-0569 | B15: OPP-23202 | C15: Relecloud | D15: Telecom | E15: RFP | F15: Data & AI | G15: Snowflake Data Cloud | H15: 1300000 | I15: 45810 | J15: 45849 | K15: 45905 | L15: Anita Rao | M15: James Patel | O15: Slalom | P15: Lost | Q15: Winner held Snowflake Elite status; we were Select | R15: =IF(AND(K15<>"",OR(P15="Won",P15="Lost")),K15-I15,"") -> 95 | S15: =IF(H15<500000,"< $0.5M",IF(H15<1000000,"$0.5M-1M",IF(H15<3000000,"$1M-3M","> $3M"))) -> $1M-3M
A16: BID-0572 | B16: OPP-23207 | C16: Adventure Works Retail | D16: Retail | E16: RFP | F16: Digital Commerce | G16: Order Management (OMS) | H16: 750000 | I16: 45824 | J16: 45863 | K16: 45912 | L16: Anita Rao | M16: James Patel | O16: EPAM; Publicis Sapient | P16: Won | Q16: OMS accelerator cut timeline by 8 weeks | R16: =IF(AND(K16<>"",OR(P16="Won",P16="Lost")),K16-I16,"") -> 88 | S16: =IF(H16<500000,"< $0.5M",IF(H16<1000000,"$0.5M-1M",IF(H16<3000000,"$1M-3M","> $3M"))) -> $0.5M-1M
A17: BID-0575 | B17: OPP-23260 | C17: Wide World Importers | D17: Retail | E17: Renewal proposal | F17: Managed Services | G17: Application Managed Services (AMS) | H17: 1050000 | I17: 45901 | J17: 45933 | K17: 45975 | L17: Rohan Kapoor | M17: James Patel | O17: Wipro | P17: Won | Q17: Renewed for 12 months only; price reduced 5% | R17: =IF(AND(K17<>"",OR(P17="Won",P17="Lost")),K17-I17,"") -> 74 | S17: =IF(H17<500000,"< $0.5M",IF(H17<1000000,"$0.5M-1M",IF(H17<3000000,"$1M-3M","> $3M"))) -> $1M-3M
A18: BID-0578 | B18: OPP-23241 | C18: Trey Research | D18: Life Sciences | E18: RFP | F18: Data & AI | G18: Snowflake Data Cloud | H18: 520000 | I18: 45880 | J18: 45912 | K18: 45954 | L18: Anita Rao | M18: Hannah Lee | O18: Slalom | P18: Won | Q18: GxP validation approach; Snowflake partnership | R18: =IF(AND(K18<>"",OR(P18="Won",P18="Lost")),K18-I18,"") -> 74 | S18: =IF(H18<500000,"< $0.5M",IF(H18<1000000,"$0.5M-1M",IF(H18<3000000,"$1M-3M","> $3M"))) -> $0.5M-1M
A19: BID-0580 | C19: VanArsdel Ltd | D19: Manufacturing | E19: RFP | F19: Application Modernization | G19: SAP Data Migration | H19: 2400000 | I19: 45894 | J19: 45933 | K19: 45982 | L19: Anita Rao | O19: Capgemini | P19: Lost | Q19: SAP migration depth and tooling; we partnered for SAP skills | R19: =IF(AND(K19<>"",OR(P19="Won",P19="Lost")),K19-I19,"") -> 88 | S19: =IF(H19<500000,"< $0.5M",IF(H19<1000000,"$0.5M-1M",IF(H19<3000000,"$1M-3M","> $3M"))) -> $1M-3M
A20: BID-0582 | B20: OPP-23270 | C20: Litware Insurance | D20: BFSI | E20: RFP | F20: Intelligent Automation | G20: Intelligent Document Processing | H20: 380000 | I20: 45915 | J20: 45947 | K20: 45996 | L20: Anita Rao | M20: Marcus Bell | O20: Genpact | P20: Won | Q20: Live demo on Litware's own FNOL documents | R20: =IF(AND(K20<>"",OR(P20="Won",P20="Lost")),K20-I20,"") -> 81 | S20: =IF(H20<500000,"< $0.5M",IF(H20<1000000,"$0.5M-1M",IF(H20<3000000,"$1M-3M","> $3M"))) -> < $0.5M
A21: BID-0584 | C21: Tailwind Traders | D21: Retail | E21: RFP | F21: Cloud & Infrastructure | G21: Data Centre Exit | H21: 3400000 | I21: 45936 | J21: 45975 | K21: 46045 | L21: Anita Rao | O21: Kyndryl | P21: Lost | Q21: Price 11% higher; winner bundled hardware buy-back | R21: =IF(AND(K21<>"",OR(P21="Won",P21="Lost")),K21-I21,"") -> 109 | S21: =IF(H21<500000,"< $0.5M",IF(H21<1000000,"$0.5M-1M",IF(H21<3000000,"$1M-3M","> $3M"))) -> > $3M
A22: BID-0585 | B22: OPP-24310 | C22: Woodgrove Bank | D22: BFSI | E22: Renewal proposal | F22: Managed Services | G22: 24x7 Service Desk | H22: 560000 | I22: 45992 | J22: 46031 | K22: 46080 | L22: Rohan Kapoor | M22: Marcus Bell | P22: Won | Q22: SLA performance 99.1%; added GenAI agent assist | R22: =IF(AND(K22<>"",OR(P22="Won",P22="Lost")),K22-I22,"") -> 88 | S22: =IF(H22<500000,"< $0.5M",IF(H22<1000000,"$0.5M-1M",IF(H22<3000000,"$1M-3M","> $3M"))) -> $0.5M-1M
A23: BID-0586 | B23: OPP-24320 | C23: Contoso Manufacturing | D23: Manufacturing | E23: Renewal proposal | F23: Managed Services | G23: Application Managed Services (AMS) | H23: 980000 | I23: 45964 | J23: 45996 | K23: 46052 | L23: Rohan Kapoor | M23: Sophie Turner | P23: Won | Q23: Incumbent; 3-year term with 4% annual productivity credit | R23: =IF(AND(K23<>"",OR(P23="Won",P23="Lost")),K23-I23,"") -> 88 | S23: =IF(H23<500000,"< $0.5M",IF(H23<1000000,"$0.5M-1M",IF(H23<3000000,"$1M-3M","> $3M"))) -> $0.5M-1M
A24: BID-0587 | C24: Graphic Design Institute | D24: Education | E24: RFP | F24: Cybersecurity | G24: Zero Trust Assessment | H24: 350000 | I24: 45971 | J24: 46003 | K24: 46059 | L24: Anita Rao | O24: Optiv | P24: Lost | Q24: Specialist security firm with education references | R24: =IF(AND(K24<>"",OR(P24="Won",P24="Lost")),K24-I24,"") -> 88 | S24: =IF(H24<500000,"< $0.5M",IF(H24<1000000,"$0.5M-1M",IF(H24<3000000,"$1M-3M","> $3M"))) -> < $0.5M
A25: BID-0588 | B25: OPP-24131 | C25: Tailspin Airlines | D25: Travel & Transport | E25: Proactive proposal | F25: Cloud & Infrastructure | G25: AWS Migration Factory | H25: 1100000 | I25: 46069 | J25: 46101 | K25: 46185 | L25: Rohan Kapoor | M25: Sophie Turner | N25: AWS | P25: Won | Q25: Wave 1 delivered on time; MAP credits lowered client cost | R25: =IF(AND(K25<>"",OR(P25="Won",P25="Lost")),K25-I25,"") -> 116 | S25: =IF(H25<500000,"< $0.5M",IF(H25<1000000,"$0.5M-1M",IF(H25<3000000,"$1M-3M","> $3M"))) -> $1M-3M
A26: BID-0589 | B26: OPP-24270 | C26: Alpine Ski House | D26: Hospitality | E26: Proactive proposal | F26: Cloud & Infrastructure | G26: Azure Landing Zone | H26: 320000 | I26: 46076 | J26: 46094 | K26: 46129 | L26: Rohan Kapoor | M26: James Patel | P26: Won | Q26: Azure Migration Assessment offer converted | R26: =IF(AND(K26<>"",OR(P26="Won",P26="Lost")),K26-I26,"") -> 53 | S26: =IF(H26<500000,"< $0.5M",IF(H26<1000000,"$0.5M-1M",IF(H26<3000000,"$1M-3M","> $3M"))) -> < $0.5M
A27: BID-0590 | B27: OPP-24250 | C27: Relecloud | D27: Telecom | E27: Proactive proposal | F27: Cybersecurity | G27: Zero Trust Assessment | H27: 180000 | I27: 46083 | J27: 46108 | K27: 46147 | L27: Rohan Kapoor | M27: James Patel | P27: Won | Q27: Existing AIOps relationship; fixed-fee 8-week assessment | R27: =IF(AND(K27<>"",OR(P27="Won",P27="Lost")),K27-I27,"") -> 64 | S27: =IF(H27<500000,"< $0.5M",IF(H27<1000000,"$0.5M-1M",IF(H27<3000000,"$1M-3M","> $3M"))) -> < $0.5M
A28: BID-0591 | B28: OPP-24300 | C28: Fabrikam Health | D28: Healthcare | E28: Proactive proposal | F28: Managed Services | G28: Application Managed Services (AMS) | H28: 420000 | I28: 46034 | J28: 46059 | K28: 46101 | L28: Rohan Kapoor | M28: Priya Raman | P28: Won | Q28: Incumbent AMS; CSAT 8.7 | R28: =IF(AND(K28<>"",OR(P28="Won",P28="Lost")),K28-I28,"") -> 67 | S28: =IF(H28<500000,"< $0.5M",IF(H28<1000000,"$0.5M-1M",IF(H28<3000000,"$1M-3M","> $3M"))) -> < $0.5M
A29: BID-0592 | B29: OPP-24330 | C29: Adventure Works Retail | D29: Retail | E29: RFP | F29: Data & AI | G29: Microsoft Fabric Analytics | H29: 450000 | I29: 46083 | J29: 46115 | K29: 46171 | L29: Anita Rao | M29: James Patel | N29: Microsoft | O29: EPAM | P29: Lost | Q29: Incumbent extended; our timeline 6 weeks longer | R29: =IF(AND(K29<>"",OR(P29="Won",P29="Lost")),K29-I29,"") -> 88 | S29: =IF(H29<500000,"< $0.5M",IF(H29<1000000,"$0.5M-1M",IF(H29<3000000,"$1M-3M","> $3M"))) -> < $0.5M
A30: BID-0594 | B30: OPP-24280 | C30: Fourth Coffee | D30: Retail | E30: RFP | F30: Digital Commerce | G30: Order Management (OMS) | H30: 410000 | I30: 46118 | J30: 46150 | K30: 46199 | L30: Anita Rao | M30: James Patel | O30: EPAM | P30: Won | Q30: Retail OMS reference (Adventure Works); 10-week MVP | R30: =IF(AND(K30<>"",OR(P30="Won",P30="Lost")),K30-I30,"") -> 81 | S30: =IF(H30<500000,"< $0.5M",IF(H30<1000000,"$0.5M-1M",IF(H30<3000000,"$1M-3M","> $3M"))) -> < $0.5M
A31: BID-0595 | B31: OPP-24340 | C31: Trey Research | D31: Life Sciences | E31: Proactive proposal | F31: Data & AI | G31: Snowflake Data Cloud | H31: 260000 | I31: 46041 | J31: 46066 | K31: 46094 | L31: Rohan Kapoor | M31: Hannah Lee | P31: Won | Q31: Follow-on to research data platform | R31: =IF(AND(K31<>"",OR(P31="Won",P31="Lost")),K31-I31,"") -> 53 | S31: =IF(H31<500000,"< $0.5M",IF(H31<1000000,"$0.5M-1M",IF(H31<3000000,"$1M-3M","> $3M"))) -> < $0.5M
A32: BID-0597 | B32: OPP-24140 | C32: Contoso Manufacturing | D32: Manufacturing | E32: RFP | F32: Data & AI | G32: Advanced Analytics & ML | H32: 1900000 | I32: 46160 | J32: 46199 | K32: 46248 | L32: Anita Rao | M32: Sophie Turner | N32: Microsoft | O32: Capgemini; HCLTech | P32: Lost | Q32: Price 14% above winner; weaker OT/IoT plant-floor references | R32: =IF(AND(K32<>"",OR(P32="Won",P32="Lost")),K32-I32,"") -> 88 | S32: =IF(H32<500000,"< $0.5M",IF(H32<1000000,"$0.5M-1M",IF(H32<3000000,"$1M-3M","> $3M"))) -> $1M-3M
A33: BID-0598 | B33: OPP-24290 | C33: Proseware Inc | D33: Technology | E33: Proactive proposal | F33: Application Modernization | G33: Legacy to Cloud-Native | H33: 280000 | I33: 46188 | J33: 46220 | K33: 46262 | L33: Rohan Kapoor | M33: Hannah Lee | P33: Won | Q33: AWS referral; SaaS factory blueprint | R33: =IF(AND(K33<>"",OR(P33="Won",P33="Lost")),K33-I33,"") -> 74 | S33: =IF(H33<500000,"< $0.5M",IF(H33<1000000,"$0.5M-1M",IF(H33<3000000,"$1M-3M","> $3M"))) -> < $0.5M
A34: BID-0599 | B34: OPP-24350 | C34: Relecloud | D34: Telecom | E34: RFP | F34: Application Modernization | G34: Legacy to Cloud-Native | H34: 1600000 | I34: 46146 | J34: 46185 | K34: 46234 | L34: Anita Rao | M34: James Patel | O34: Tech Mahindra | P34: Lost | Q34: Telecom OSS/BSS depth; winner had BSS product partnership | R34: =IF(AND(K34<>"",OR(P34="Won",P34="Lost")),K34-I34,"") -> 88 | S34: =IF(H34<500000,"< $0.5M",IF(H34<1000000,"$0.5M-1M",IF(H34<3000000,"$1M-3M","> $3M"))) -> $1M-3M
A35: BID-0601 | B35: OPP-24170 | C35: Wingtip Logistics | D35: Logistics | E35: Proactive proposal | F35: Data & AI | G35: Advanced Analytics & ML | H35: 850000 | I35: 46153 | J35: 46178 | K35: 46223 | L35: Rohan Kapoor | M35: Sophie Turner | N35: Databricks | P35: Won | Q35: Phase 1 outcomes (7.4% fuel saving); incumbent advantage | R35: =IF(AND(K35<>"",OR(P35="Won",P35="Lost")),K35-I35,"") -> 70 | S35: =IF(H35<500000,"< $0.5M",IF(H35<1000000,"$0.5M-1M",IF(H35<3000000,"$1M-3M","> $3M"))) -> $0.5M-1M
A36: BID-0603 | B36: OPP-24180 | C36: Relecloud | D36: Telecom | E36: Renewal proposal | F36: Managed Services | G36: AIOps Managed Services | H36: 2400000 | I36: 46237 | J36: 46276 | K36: 46339 | L36: Rohan Kapoor | M36: James Patel | P36: Submitted - in negotiation | R36: =IF(AND(K36<>"",OR(P36="Won",P36="Lost")),K36-I36,"") | S36: =IF(H36<500000,"< $0.5M",IF(H36<1000000,"$0.5M-1M",IF(H36<3000000,"$1M-3M","> $3M"))) -> $1M-3M
A37: BID-0608 | B37: OPP-24130 | C37: Tailspin Airlines | D37: Travel & Transport | E37: RFP | F37: Application Modernization | G37: Legacy to Cloud-Native | H37: 2200000 | I37: 46230 | J37: 46269 | K37: 46318 | L37: Anita Rao | M37: Sophie Turner | N37: AWS | O37: TCS; Cognizant | P37: Shortlisted - orals held 30 Sep | R37: =IF(AND(K37<>"",OR(P37="Won",P37="Lost")),K37-I37,"") | S37: =IF(H37<500000,"< $0.5M",IF(H37<1000000,"$0.5M-1M",IF(H37<3000000,"$1M-3M","> $3M"))) -> $1M-3M
A38: BID-0609 | C38: Bellows College | D38: Education | E38: RFI | F38: Data & AI | H38: 600000 | I38: 46238 | K38: 46240 | L38: Anita Rao | P38: No-bid | Q38: Outside target industries; low strategic fit | R38: =IF(AND(K38<>"",OR(P38="Won",P38="Lost")),K38-I38,"") | S38: =IF(H38<500000,"< $0.5M",IF(H38<1000000,"$0.5M-1M",IF(H38<3000000,"$1M-3M","> $3M"))) -> $0.5M-1M
A39: BID-0611 | B39: OPP-24200 | C39: Wide World Importers | D39: Retail | E39: Renewal proposal | F39: Managed Services | G39: Application Managed Services (AMS) | H39: 1100000 | I39: 46251 | J39: 46286 | K39: 46325 | L39: Rohan Kapoor | M39: James Patel | O39: Wipro | P39: Submitted - at risk | R39: =IF(AND(K39<>"",OR(P39="Won",P39="Lost")),K39-I39,"") | S39: =IF(H39<500000,"< $0.5M",IF(H39<1000000,"$0.5M-1M",IF(H39<3000000,"$1M-3M","> $3M"))) -> $1M-3M
A40: BID-0612 | B40: OPP-24120 | C40: Woodgrove Bank | D40: BFSI | E40: RFP | F40: Data & AI | G40: Cloud Data Platform (Azure Databricks) | H40: 3100000 | I40: 46258 | J40: 46290 | K40: 46346 | L40: Anita Rao | M40: Marcus Bell | N40: Microsoft | O40: Accenture; Infosys | P40: Submitted - BAFO requested | R40: =IF(AND(K40<>"",OR(P40="Won",P40="Lost")),K40-I40,"") | S40: =IF(H40<500000,"< $0.5M",IF(H40<1000000,"$0.5M-1M",IF(H40<3000000,"$1M-3M","> $3M"))) -> > $3M
A41: BID-0614 | B41: OPP-24220 | C41: Meridian Bank | D41: BFSI | E41: RFP | F41: Data & AI | G41: Cloud Data Platform (Azure Databricks) | H41: 2400000 | I41: 46252 | J41: 46283 | K41: 46374 | L41: Anita Rao | M41: Marcus Bell | N41: Microsoft | O41: Accenture; Cognizant (incumbent DW) | P41: Shortlisted | R41: =IF(AND(K41<>"",OR(P41="Won",P41="Lost")),K41-I41,"") | S41: =IF(H41<500000,"< $0.5M",IF(H41<1000000,"$0.5M-1M",IF(H41<3000000,"$1M-3M","> $3M"))) -> $1M-3M
...

Sheet Win Rate Summary
A1: Win Rate Summary (decided bids)
A2: Formulas read the Bid Tracker sheet. Win rate = Won / (Won + Lost); No-bids excluded.
A3: Classification: Internal
A5: By service line
A6: Segment | B6: Bids decided | C6: Won | D6: Lost | E6: Win rate | F6: Won value (USD) | G6: Avg cycle (days)
A7: Cloud & Infrastructure | B7: =C7+D7 -> 4 | C7: =COUNTIFS('Bid Tracker'!$F$6:$F$47,"Cloud & Infrastructure",'Bid Tracker'!$P$6:$P$47,"Won") -> 3 | D7: =COUNTIFS('Bid Tracker'!$F$6:$F$47,"Cloud & Infrastructure",'Bid Tracker'!$P$6:$P$47,"Lost") -> 1 | E7: =IF(B7=0,"",C7/B7) -> 0.75 | F7: =SUMIFS('Bid Tracker'!$H$6:$H$47,'Bid Tracker'!$F$6:$F$47,"Cloud & Infrastructure",'Bid Tracker'!$P$6:$P$47,"Won") -> 2820000 | G7: =IFERROR(AVERAGEIFS('Bid Tracker'!$R$6:$R$47,'Bid Tracker'!$F$6:$F$47,"Cloud & Infrastructure",'Bid Tracker'!$R$6:$R$47,"<>"),"") -> 86.25
A8: Data & AI | B8: =C8+D8 -> 10 | C8: =COUNTIFS('Bid Tracker'!$F$6:$F$47,"Data & AI",'Bid Tracker'!$P$6:$P$47,"Won") -> 6 | D8: =COUNTIFS('Bid Tracker'!$F$6:$F$47,"Data & AI",'Bid Tracker'!$P$6:$P$47,"Lost") -> 4 | E8: =IF(B8=0,"",C8/B8) -> 0.6 | F8: =SUMIFS('Bid Tracker'!$H$6:$H$47,'Bid Tracker'!$F$6:$F$47,"Data & AI",'Bid Tracker'!$P$6:$P$47,"Won") -> 6430000 | G8: =IFERROR(AVERAGEIFS('Bid Tracker'!$R$6:$R$47,'Bid Tracker'!$F$6:$F$47,"Data & AI",'Bid Tracker'!$R$6:$R$47,"<>"),"") -> 81.3
A9: Application Modernization | B9: =C9+D9 -> 6 | C9: =COUNTIFS('Bid Tracker'!$F$6:$F$47,"Application Modernization",'Bid Tracker'!$P$6:$P$47,"Won") -> 2 | D9: =COUNTIFS('Bid Tracker'!$F$6:$F$47,"Application Modernization",'Bid Tracker'!$P$6:$P$47,"Lost") -> 4 | E9: =IF(B9=0,"",C9/B9) -> 0.33333333 | F9: =SUMIFS('Bid Tracker'!$H$6:$H$47,'Bid Tracker'!$F$6:$F$47,"Application Modernization",'Bid Tracker'!$P$6:$P$47,"Won") -> 3880000 | G9: =IFERROR(AVERAGEIFS('Bid Tracker'!$R$6:$R$47,'Bid Tracker'!$F$6:$F$47,"Application Modernization",'Bid Tracker'!$R$6:$R$47,"<>"),"") -> 79.833333
A10: Digital Commerce | B10: =C10+D10 -> 3 | C10: =COUNTIFS('Bid Tracker'!$F$6:$F$47,"Digital Commerce",'Bid Tracker'!$P$6:$P$47,"Won") -> 2 | D10: =COUNTIFS('Bid Tracker'!$F$6:$F$47,"Digital Commerce",'Bid Tracker'!$P$6:$P$47,"Lost") -> 1 | E10: =IF(B10=0,"",C10/B10) -> 0.66666667 | F10: =SUMIFS('Bid Tracker'!$H$6:$H$47,'Bid Tracker'!$F$6:$F$47,"Digital Commerce",'Bid Tracker'!$P$6:$P$47,"Won") -> 1160000 | G10: =IFERROR(AVERAGEIFS('Bid Tracker'!$R$6:$R$47,'Bid Tracker'!$F$6:$F$47,"Digital Commerce",'Bid Tracker'!$R$6:$R$47,"<>"),"") -> 83.333333
A11: Managed Services | B11: =C11+D11 -> 4 | C11: =COUNTIFS('Bid Tracker'!$F$6:$F$47,"Managed Services",'Bid Tracker'!$P$6:$P$47,"Won") -> 4 | D11: =COUNTIFS('Bid Tracker'!$F$6:$F$47,"Managed Services",'Bid Tracker'!$P$6:$P$47,"Lost") -> 0 | E11: =IF(B11=0,"",C11/B11) -> 1 | F11: =SUMIFS('Bid Tracker'!$H$6:$H$47,'Bid Tracker'!$F$6:$F$47,"Managed Services",'Bid Tracker'!$P$6:$P$47,"Won") -> 3010000 | G11: =IFERROR(AVERAGEIFS('Bid Tracker'!$R$6:$R$47,'Bid Tracker'!$F$6:$F$47,"Managed Services",'Bid Tracker'!$R$6:$R$47,"<>"),"") -> 79.25
A12: Cybersecurity | B12: =C12+D12 -> 2 | C12: =COUNTIFS('Bid Tracker'!$F$6:$F$47,"Cybersecurity",'Bid Tracker'!$P$6:$P$47,"Won") -> 1 | D12: =COUNTIFS('Bid Tracker'!$F$6:$F$47,"Cybersecurity",'Bid Tracker'!$P$6:$P$47,"Lost") -> 1 | E12: =IF(B12=0,"",C12/B12) -> 0.5 | F12: =SUMIFS('Bid Tracker'!$H$6:$H$47,'Bid Tracker'!$F$6:$F$47,"Cybersecurity",'Bid Tracker'!$P$6:$P$47,"Won") -> 180000 | G12: =IFERROR(AVERAGEIFS('Bid Tracker'!$R$6:$R$47,'Bid Tracker'!$F$6:$F$47,"Cybersecurity",'Bid Tracker'!$R$6:$R$47,"<>"),"") -> 76
A13: Intelligent Automation | B13: =C13+D13 -> 1 | C13: =COUNTIFS('Bid Tracker'!$F$6:$F$47,"Intelligent Automation",'Bid Tracker'!$P$6:$P$47,"Won") -> 1 | D13: =COUNTIFS('Bid Tracker'!$F$6:$F$47,"Intelligent Automation",'Bid Tracker'!$P$6:$P$47,"Lost") -> 0 | E13: =IF(B13=0,"",C13/B13) -> 1 | F13: =SUMIFS('Bid Tracker'!$H$6:$H$47,'Bid Tracker'!$F$6:$F$47,"Intelligent Automation",'Bid Tracker'!$P$6:$P$47,"Won") -> 380000 | G13: =IFERROR(AVERAGEIFS('Bid Tracker'!$R$6:$R$47,'Bid Tracker'!$F$6:$F$47,"Intelligent Automation",'Bid Tracker'!$R$6:$R$47,"<>"),"") -> 81
A15: By industry
A16: Segment | B16: Bids decided | C16: Won | D16: Lost | E16: Win rate | F16: Won value (USD) | G16: Avg cycle (days)
A17: BFSI | B17: =C17+D17 -> 2 | C17: =COUNTIFS('Bid Tracker'!$D$6:$D$47,"BFSI",'Bid Tracker'!$P$6:$P$47,"Won") -> 2 | D17: =COUNTIFS('Bid Tracker'!$D$6:$D$47,"BFSI",'Bid Tracker'!$P$6:$P$47,"Lost") -> 0 | E17: =IF(B17=0,"",C17/B17) -> 1 | F17: =SUMIFS('Bid Tracker'!$H$6:$H$47,'Bid Tracker'!$D$6:$D$47,"BFSI",'Bid Tracker'!$P$6:$P$47,"Won") -> 940000 | G17: =IFERROR(AVERAGEIFS('Bid Tracker'!$R$6:$R$47,'Bid Tracker'!$D$6:$D$47,"BFSI",'Bid Tracker'!$R$6:$R$47,"<>"),"") -> 84.5
A18: Education | B18: =C18+D18 -> 1 | C18: =COUNTIFS('Bid Tracker'!$D$6:$D$47,"Education",'Bid Tracker'!$P$6:$P$47,"Won") -> 0 | D18: =COUNTIFS('Bid Tracker'!$D$6:$D$47,"Education",'Bid Tracker'!$P$6:$P$47,"Lost") -> 1 | E18: =IF(B18=0,"",C18/B18) -> 0 | F18: =SUMIFS('Bid Tracker'!$H$6:$H$47,'Bid Tracker'!$D$6:$D$47,"Education",'Bid Tracker'!$P$6:$P$47,"Won") -> 0 | G18: =IFERROR(AVERAGEIFS('Bid Tracker'!$R$6:$R$47,'Bid Tracker'!$D$6:$D$47,"Education",'Bid Tracker'!$R$6:$R$47,"<>"),"") -> 88
A19: Healthcare | B19: =C19+D19 -> 4 | C19: =COUNTIFS('Bid Tracker'!$D$6:$D$47,"Healthcare",'Bid Tracker'!$P$6:$P$47,"Won") -> 3 | D19: =COUNTIFS('Bid Tracker'!$D$6:$D$47,"Healthcare",'Bid Tracker'!$P$6:$P$47,"Lost") -> 1 | E19: =IF(B19=0,"",C19/B19) -> 0.75 | F19: =SUMIFS('Bid Tracker'!$H$6:$H$47,'Bid Tracker'!$D$6:$D$47,"Healthcare",'Bid Tracker'!$P$6:$P$47,"Won") -> 3620000 | G19: =IFERROR(AVERAGEIFS('Bid Tracker'!$R$6:$R$47,'Bid Tracker'!$D$6:$D$47,"Healthcare",'Bid Tracker'!$R$6:$R$47,"<>"),"") -> 82.75
A20: Hospitality | B20: =C20+D20 -> 1 | C20: =COUNTIFS('Bid Tracker'!$D$6:$D$47,"Hospitality",'Bid Tracker'!$P$6:$P$47,"Won") -> 1 | D20: =COUNTIFS('Bid Tracker'!$D$6:$D$47,"Hospitality",'Bid Tracker'!$P$6:$P$47,"Lost") -> 0 | E20: =IF(B20=0,"",C20/B20) -> 1 | F20: =SUMIFS('Bid Tracker'!$H$6:$H$47,'Bid Tracker'!$D$6:$D$47,"Hospitality",'Bid Tracker'!$P$6:$P$47,"Won") -> 320000 | G20: =IFERROR(AVERAGEIFS('Bid Tracker'!$R$6:$R$47,'Bid Tracker'!$D$6:$D$47,"Hospitality",'Bid Tracker'!$R$6:$R$47,"<>"),"") -> 53
A21: Life Sciences | B21: =C21+D21 -> 2 | C21: =COUNTIFS('Bid Tracker'!$D$6:$D$47,"Life Sciences",'Bid Tracker'!$P$6:$P$47,"Won") -> 2 | D21: =COUNTIFS('Bid Tracker'!$D$6:$D$47,"Life Sciences",'Bid Tracker'!$P$6:$P$47,"Lost") -> 0 | E21: =IF(B21=0,"",C21/B21) -> 1 | F21: =SUMIFS('Bid Tracker'!$H$6:$H$47,'Bid Tracker'!$D$6:$D$47,"Life Sciences",'Bid Tracker'!$P$6:$P$47,"Won") -> 780000 | G21: =IFERROR(AVERAGEIFS('Bid Tracker'!$R$6:$R$47,'Bid Tracker'!$D$6:$D$47,"Life Sciences",'Bid Tracker'!$R$6:$R$47,"<>"),"") -> 63.5
A22: Logistics | B22: =C22+D22 -> 2 | C22: =COUNTIFS('Bid Tracker'!$D$6:$D$47,"Logistics",'Bid Tracker'!$P$6:$P$47,"Won") -> 2 | D22: =COUNTIFS('Bid Tracker'!$D$6:$D$47,"Logistics",'Bid Tracker'!$P$6:$P$47,"Lost") -> 0 | E22: =IF(B22=0,"",C22/B22) -> 1 | F22: =SUMIFS('Bid Tracker'!$H$6:$H$47,'Bid Tracker'!$D$6:$D$47,"Logistics",'Bid Tracker'!$P$6:$P$47,"Won") -> 2450000 | G22: =IFERROR(AVERAGEIFS('Bid Tracker'!$R$6:$R$47,'Bid Tracker'!$D$6:$D$47,"Logistics",'Bid Tracker'!$R$6:$R$47,"<>"),"") -> 79
A23: Manufacturing | B23: =C23+D23 -> 4 | C23: =COUNTIFS('Bid Tracker'!$D$6:$D$47,"Manufacturing",'Bid Tracker'!$P$6:$P$47,"Won") -> 1 | D23: =COUNTIFS('Bid Tracker'!$D$6:$D$47,"Manufacturing",'Bid Tracker'!$P$6:$P$47,"Lost") -> 3 | E23: =IF(B23=0,"",C23/B23) -> 0.25 | F23: =SUMIFS('Bid Tracker'!$H$6:$H$47,'Bid Tracker'!$D$6:$D$47,"Manufacturing",'Bid Tracker'!$P$6:$P$47,"Won") -> 980000 | G23: =IFERROR(AVERAGEIFS('Bid Tracker'!$R$6:$R$47,'Bid Tracker'!$D$6:$D$47,"Manufacturing",'Bid Tracker'!$R$6:$R$47,"<>"),"") -> 86.25
A24: Media | B24: =C24+D24 -> 1 | C24: =COUNTIFS('Bid Tracker'!$D$6:$D$47,"Media",'Bid Tracker'!$P$6:$P$47,"Won") -> 0 | D24: =COUNTIFS('Bid Tracker'!$D$6:$D$47,"Media",'Bid Tracker'!$P$6:$P$47,"Lost") -> 1 | E24: =IF(B24=0,"",C24/B24) -> 0 | F24: =SUMIFS('Bid Tracker'!$H$6:$H$47,'Bid Tracker'!$D$6:$D$47,"Media",'Bid Tracker'!$P$6:$P$47,"Won") -> 0 | G24: =IFERROR(AVERAGEIFS('Bid Tracker'!$R$6:$R$47,'Bid Tracker'!$D$6:$D$47,"Media",'Bid Tracker'!$R$6:$R$47,"<>"),"") -> 39
A25: Retail | B25: =C25+D25 -> 7 | C25: =COUNTIFS('Bid Tracker'!$D$6:$D$47,"Retail",'Bid Tracker'!$P$6:$P$47,"Won") -> 4 | D25: =COUNTIFS('Bid Tracker'!$D$6:$D$47,"Retail",'Bid Tracker'!$P$6:$P$47,"Lost") -> 3 | E25: =IF(B25=0,"",C25/B25) -> 0.57142857 | F25: =SUMIFS('Bid Tracker'!$H$6:$H$47,'Bid Tracker'!$D$6:$D$47,"Retail",'Bid Tracker'!$P$6:$P$47,"Won") -> 5810000 | G25: =IFERROR(AVERAGEIFS('Bid Tracker'!$R$6:$R$47,'Bid Tracker'!$D$6:$D$47,"Retail",'Bid Tracker'!$R$6:$R$47,"<>"),"") -> 89
A26: Technology | B26: =C26+D26 -> 1 | C26: =COUNTIFS('Bid Tracker'!$D$6:$D$47,"Technology",'Bid Tracker'!$P$6:$P$47,"Won") -> 1 | D26: =COUNTIFS('Bid Tracker'!$D$6:$D$47,"Technology",'Bid Tracker'!$P$6:$P$47,"Lost") -> 0 | E26: =IF(B26=0,"",C26/B26) -> 1 | F26: =SUMIFS('Bid Tracker'!$H$6:$H$47,'Bid Tracker'!$D$6:$D$47,"Technology",'Bid Tracker'!$P$6:$P$47,"Won") -> 280000 | G26: =IFERROR(AVERAGEIFS('Bid Tracker'!$R$6:$R$47,'Bid Tracker'!$D$6:$D$47,"Technology",'Bid Tracker'!$R$6:$R$47,"<>"),"") -> 74
A27: Telecom | B27: =C27+D27 -> 3 | C27: =COUNTIFS('Bid Tracker'!$D$6:$D$47,"Telecom",'Bid Tracker'!$P$6:$P$47,"Won") -> 1 | D27: =COUNTIFS('Bid Tracker'!$D$6:$D$47,"Telecom",'Bid Tracker'!$P$6:$P$47,"Lost") -> 2 | E27: =IF(B27=0,"",C27/B27) -> 0.33333333 | F27: =SUMIFS('Bid Tracker'!$H$6:$H$47,'Bid Tracker'!$D$6:$D$47,"Telecom",'Bid Tracker'!$P$6:$P$47,"Won") -> 180000 | G27: =IFERROR(AVERAGEIFS('Bid Tracker'!$R$6:$R$47,'Bid Tracker'!$D$6:$D$47,"Telecom",'Bid Tracker'!$R$6:$R$47,"<>"),"") -> 82.333333
A28: Travel & Transport | B28: =C28+D28 -> 2 | C28: =COUNTIFS('Bid Tracker'!$D$6:$D$47,"Travel & Transport",'Bid Tracker'!$P$6:$P$47,"Won") -> 2 | D28: =COUNTIFS('Bid Tracker'!$D$6:$D$47,"Travel & Transport",'Bid Tracker'!$P$6:$P$47,"Lost") -> 0 | E28: =IF(B28=0,"",C28/B28) -> 1 | F28: =SUMIFS('Bid Tracker'!$H$6:$H$47,'Bid Tracker'!$D$6:$D$47,"Travel & Transport",'Bid Tracker'!$P$6:$P$47,"Won") -> 2500000 | G28: =IFERROR(AVERAGEIFS('Bid Tracker'!$R$6:$R$47,'Bid Tracker'!$D$6:$D$47,"Travel & Transport",'Bid Tracker'!$R$6:$R$47,"<>"),"") -> 91.5
A30: By deal size
A31: Segment | B31: Bids decided | C31: Won | D31: Lost | E31: Win rate | F31: Won value (USD) | G31: Avg cycle (days)
A32: < $0.5M | B32: =C32+D32 -> 9 | C32: =COUNTIFS('Bid Tracker'!$S$6:$S$47,"< $0.5M",'Bid Tracker'!$P$6:$P$47,"Won") -> 7 | D32: =COUNTIFS('Bid Tracker'!$S$6:$S$47,"< $0.5M",'Bid Tracker'!$P$6:$P$47,"Lost") -> 2 | E32: =IF(B32=0,"",C32/B32) -> 0.77777778 | F32: =SUMIFS('Bid Tracker'!$H$6:$H$47,'Bid Tracker'!$S$6:$S$47,"< $0.5M",'Bid Tracker'!$P$6:$P$47,"Won") -> 2250000 | G32: =IFERROR(AVERAGEIFS('Bid Tracker'!$R$6:$R$47,'Bid Tracker'!$S$6:$S$47,"< $0.5M",'Bid Tracker'!$R$6:$R$47,"<>"),"") -> 72.111111
A33: $0.5M-1M | B33: =C33+D33 -> 7 | C33: =COUNTIFS('Bid Tracker'!$S$6:$S$47,"$0.5M-1M",'Bid Tracker'!$P$6:$P$47,"Won") -> 5 | D33: =COUNTIFS('Bid Tracker'!$S$6:$S$47,"$0.5M-1M",'Bid Tracker'!$P$6:$P$47,"Lost") -> 2 | E33: =IF(B33=0,"",C33/B33) -> 0.71428571 | F33: =SUMIFS('Bid Tracker'!$H$6:$H$47,'Bid Tracker'!$S$6:$S$47,"$0.5M-1M",'Bid Tracker'!$P$6:$P$47,"Won") -> 3660000 | G33: =IFERROR(AVERAGEIFS('Bid Tracker'!$R$6:$R$47,'Bid Tracker'!$S$6:$S$47,"$0.5M-1M",'Bid Tracker'!$R$6:$R$47,"<>"),"") -> 81.428571
A34: $1M-3M | B34: =C34+D34 -> 12 | C34: =COUNTIFS('Bid Tracker'!$S$6:$S$47,"$1M-3M",'Bid Tracker'!$P$6:$P$47,"Won") -> 6 | D34: =COUNTIFS('Bid Tracker'!$S$6:$S$47,"$1M-3M",'Bid Tracker'!$P$6:$P$47,"Lost") -> 6 | E34: =IF(B34=0,"",C34/B34) -> 0.5 | F34: =SUMIFS('Bid Tracker'!$H$6:$H$47,'Bid Tracker'!$S$6:$S$47,"$1M-3M",'Bid Tracker'!$P$6:$P$47,"Won") -> 8350000 | G34: =IFERROR(AVERAGEIFS('Bid Tracker'!$R$6:$R$47,'Bid Tracker'!$S$6:$S$47,"$1M-3M",'Bid Tracker'!$R$6:$R$47,"<>"),"") -> 83.916667
A35: > $3M | B35: =C35+D35 -> 2 | C35: =COUNTIFS('Bid Tracker'!$S$6:$S$47,"> $3M",'Bid Tracker'!$P$6:$P$47,"Won") -> 1 | D35: =COUNTIFS('Bid Tracker'!$S$6:$S$47,"> $3M",'Bid Tracker'!$P$6:$P$47,"Lost") -> 1 | E35: =IF(B35=0,"",C35/B35) -> 0.5 | F35: =SUMIFS('Bid Tracker'!$H$6:$H$47,'Bid Tracker'!$S$6:$S$47,"> $3M",'Bid Tracker'!$P$6:$P$47,"Won") -> 3600000 | G35: =IFERROR(AVERAGEIFS('Bid Tracker'!$R$6:$R$47,'Bid Tracker'!$S$6:$S$47,"> $3M",'Bid Tracker'!$R$6:$R$47,"<>"),"") -> 105.5
A37: By bid type
A38: Segment | B38: Bids decided | C38: Won | D38: Lost | E38: Win rate | F38: Won value (USD) | G38: Avg cycle (days)
A39: RFP | B39: =C39+D39 -> 18 | C39: =COUNTIFS('Bid Tracker'!$E$6:$E$47,"RFP",'Bid Tracker'!$P$6:$P$47,"Won") -> 8 | D39: =COUNTIFS('Bid Tracker'!$E$6:$E$47,"RFP",'Bid Tracker'!$P$6:$P$47,"Lost") -> 10 | E39: =IF(B39=0,"",C39/B39) -> 0.44444444 | F39: =SUMIFS('Bid Tracker'!$H$6:$H$47,'Bid Tracker'!$E$6:$E$47,"RFP",'Bid Tracker'!$P$6:$P$47,"Won") -> 10460000 | G39: =IFERROR(AVERAGEIFS('Bid Tracker'!$R$6:$R$47,'Bid Tracker'!$E$6:$E$47,"RFP",'Bid Tracker'!$R$6:$R$47,"<>"),"") -> 88
A40: RFI | B40: =C40+D40 -> 1 | C40: =COUNTIFS('Bid Tracker'!$E$6:$E$47,"RFI",'Bid Tracker'!$P$6:$P$47,"Won") -> 0 | D40: =COUNTIFS('Bid Tracker'!$E$6:$E$47,"RFI",'Bid Tracker'!$P$6:$P$47,"Lost") -> 1 | E40: =IF(B40=0,"",C40/B40) -> 0 | F40: =SUMIFS('Bid Tracker'!$H$6:$H$47,'Bid Tracker'!$E$6:$E$47,"RFI",'Bid Tracker'!$P$6:$P$47,"Won") -> 0 | G40: =IFERROR(AVERAGEIFS('Bid Tracker'!$R$6:$R$47,'Bid Tracker'!$E$6:$E$47,"RFI",'Bid Tracker'!$R$6:$R$47,"<>"),"") -> 39
A41: Proactive proposal | B41: =C41+D41 -> 8 | C41: =COUNTIFS('Bid Tracker'!$E$6:$E$47,"Proactive proposal",'Bid Tracker'!$P$6:$P$47,"Won") -> 8 | D41: =COUNTIFS('Bid Tracker'!$E$6:$E$47,"Proactive proposal",'Bid Tracker'!$P$6:$P$47,"Lost") -> 0 | E41: =IF(B41=0,"",C41/B41) -> 1 | F41: =SUMIFS('Bid Tracker'!$H$6:$H$47,'Bid Tracker'!$E$6:$E$47,"Proactive proposal",'Bid Tracker'!$P$6:$P$47,"Won") -> 4810000 | G41: =IFERROR(AVERAGEIFS('Bid Tracker'!$R$6:$R$47,'Bid Tracker'!$E$6:$E$47,"Proactive proposal",'Bid Tracker'!$R$6:$R$47,"<>"),"") -> 70.5
A42: Renewal proposal | B42: =C42+D42 -> 3 | C42: =COUNTIFS('Bid Tracker'!$E$6:$E$47,"Renewal proposal",'Bid Tracker'!$P$6:$P$47,"Won") -> 3 | D42: =COUNTIFS('Bid Tracker'!$E$6:$E$47,"Renewal proposal",'Bid Tracker'!$P$6:$P$47,"Lost") -> 0 | E42: =IF(B42=0,"",C42/B42) -> 1 | F42: =SUMIFS('Bid Tracker'!$H$6:$H$47,'Bid Tracker'!$E$6:$E$47,"Renewal proposal",'Bid Tracker'!$P$6:$P$47,"Won") -> 2590000 | G42: =IFERROR(AVERAGEIFS('Bid Tracker'!$R$6:$R$47,'Bid Tracker'!$E$6:$E$47,"Renewal proposal",'Bid Tracker'!$R$6:$R$47,"<>"),"") -> 83.333333
A44: Competitive RFP win rate is the board KPI (target 40%). Renewals and proactive proposals are tracked separately because they are largely uncontested.
A45: Source: Bid Tracker sheet. Values recalculate when the tracker changes.

Sheet Bids In Flight
A1: Bids in flight and decisions pending
A2: As of 8 Oct 2026 (week 41)
A3: Classification: Internal
A5: Bid ID | B5: Account | C5: Opportunity | D5: Type | E5: Value (USD) | F5: Submission | G5: Decision | H5: Status | I5: Days to submission | J5: Bid Manager | K5: Extensions / resubmissions
A6: BID-0608 | B6: Tailspin Airlines | C6: Crew Operations Platform Modernisation | D6: RFP | E6: 2200000 | F6: 46269 | G6: 46318 | H6: Shortlisted - orals held 30 Sep | I6: =IF(F6>=DATE(2026,10,8),F6-DATE(2026,10,8),"Submitted") -> Submitted | J6: Anita Rao
A7: BID-0603 | B7: Relecloud | C7: AIOps Managed Services Renewal | D7: Renewal proposal | E7: 2400000 | F7: 46276 | G7: 46339 | H7: Submitted - in negotiation | I7: =IF(F7>=DATE(2026,10,8),F7-DATE(2026,10,8),"Submitted") -> Submitted | J7: Rohan Kapoor
A8: BID-0614 | B8: Meridian Bank | C8: Cloud Data Platform | D8: RFP | E8: 2400000 | F8: 46283 | G8: 46374 | H8: Shortlisted | I8: =IF(F8>=DATE(2026,10,8),F8-DATE(2026,10,8),"Submitted") -> Submitted | J8: Anita Rao
A9: BID-0611 | B9: Wide World Importers | C9: WMS Support Renewal FY27 | D9: Renewal proposal | E9: 1100000 | F9: 46286 | G9: 46325 | H9: Submitted - at risk | I9: =IF(F9>=DATE(2026,10,8),F9-DATE(2026,10,8),"Submitted") -> Submitted | J9: Rohan Kapoor
A10: BID-0612 | B10: Woodgrove Bank | C10: Enterprise Data Platform Modernisation | D10: RFP | E10: 3100000 | F10: 46290 | G10: 46346 | H10: Submitted - BAFO requested | I10: =IF(F10>=DATE(2026,10,8),F10-DATE(2026,10,8),"Submitted") -> Submitted | J10: Anita Rao
A11: BID-0615 | B11: Lamna Healthcare | C11: Claims Platform Azure Migration | D11: RFP | E11: 1500000 | F11: 46297 | G11: 46356 | H11: Submitted | I11: =IF(F11>=DATE(2026,10,8),F11-DATE(2026,10,8),"Submitted") -> Submitted | J11: Rohan Kapoor | K11: Due date extended from 28 Sep to 2 Oct
A12: BID-0619 | B12: Adventure Works Retail | C12: Unified Commerce Replatform | D12: RFI | E12: 2600000 | F12: 46311 | G12: 46332 | H12: In progress | I12: =IF(F12>=DATE(2026,10,8),F12-DATE(2026,10,8),"Submitted") -> 8 | J12: Rohan Kapoor
A13: BID-0618 | B13: Calder Insurance | C13: Claims Modernisation (Guidewire ClaimCenter) | D13: RFP | E13: 5800000 | F13: 46315 | G13: 46360 | H13: In progress - drafting | I13: =IF(F13>=DATE(2026,10,8),F13-DATE(2026,10,8),"Submitted") -> 12 | J13: Anita Rao
A14: BID-0620 | B14: Trey Research | C14: GxP Data Lake on AWS | D14: RFI | E14: 1400000 | F14: 46323 | G14: 46346 | H14: Qualifying | I14: =IF(F14>=DATE(2026,10,8),F14-DATE(2026,10,8),"Submitted") -> 20 | J14: Rohan Kapoor
D16: Value in flight | E16: =SUM(E6:E14) -> 22500000
A18: Resubmissions and extensions
A19: Bid ID | B19: Account | C19: Event | D19: Original date | E19: New date | F19: Requested by
A20: BID-0612 | B20: Woodgrove Bank | C20: BAFO resubmission requested (pricing and team continuity) | D20: 46290 | E20: 46309 | F20: Brian Foster (Woodgrove sourcing)
A21: BID-0615 | B21: Lamna Healthcare | C21: Submission extension granted | D21: 46293 | E21: 46297 | F21: Visionet (Rohan Kapoor) - awaiting AMM funding confirmation
A22: BID-0608 | B22: Tailspin Airlines | C22: Decision date moved after orals | D22: 46311 | E22: 46318 | F22: Elaine Russo (Tailspin)

Sheet Upcoming RFx
A1: Upcoming RFPs and RFIs (next 120 days)
A2: Expected releases from account teams and partner intel
A3: Classification: Internal
A5: Account | B5: RFx | C5: Scope | D5: Est. value (USD) | E5: Expected release | F5: Opportunity | G5: Account Owner | H5: Priority | I5: Intel
A6: Adventure Works Retail | B6: RFP | C6: Unified commerce replatform (follow-on to RFI BID-0619) | D6: 2600000 | E6: 46342 | F6: OPP-24160 | G6: James Patel | H6: High | I6: RFI shortlist expected 6 Nov
A7: Fabrikam Health | B7: RFP | C7: Population health analytics (phase 2) | D7: 1250000 | E7: 46356 | F7: OPP-24110 | G7: Priya Raman | H7: Medium | I7: Client may sole-source if phase 1 feed stabilises
A8: Contoso Manufacturing | B8: RFP | C8: SAP S/4HANA data migration support | D8: 650000 | E8: 46363 | F8: OPP-24141 | G8: Sophie Turner | H8: Medium | I8: Capgemini (Smart Factory winner) likely to bid
A9: Lamna Healthcare | B9: RFI | C9: GenAI member service copilot | D9: 600000 | E9: 46335 | F9: OPP-24260 | G9: Hannah Lee | H9: Medium | I9: Came out of Boston roundtable (CMP-2603)
A10: Relecloud | B10: RFP | C10: OSS/BSS modernisation - phase 2 (re-tender) | D10: 1900000 | E10: 46405 | G10: James Patel | H10: Low | I10: We lost phase 1 discovery (BID-0599); re-tender after client leadership change
A11: Woodgrove Bank | B11: RFI | C11: Managed SOC (MXDR) | D11: 900000 | E11: 46398 | F11: OPP-24121 | G11: Marcus Bell | H11: Medium | I11: Microsoft Sentinel-based; CISO Nadia Petrova not yet engaged

Sheet Lists
A1: Status values | B1: Bid types
A2: Qualifying | B2: RFI
A3: In progress | B3: RFP
A4: Submitted | B4: RFQ
A5: Shortlisted | B5: Proactive proposal
A6: Won | B6: Renewal proposal
A7: Lost
A8: No-bid
A9: Withdrawn
